Workbook

Sheet Read Me
A1: Unit Test Cases - Student Portal (Assignment 3: Build Unit Test Automation Solution)
A2: Authors: Maryam Fatima (24F-3044) and Huda Asif (24F-3111) | Application under test: src/student_portal.py
A4: Sheet 'Data Driven Cases': the test cases that are executed from external CSV files (Task 3). The automated test tests/data_driven/test_excel_driven.py reads this sheet, opens the CSV named in column 'Test Data File' and runs every row.
A5: Sheet 'Test Inventory': every automated unit test function with its module, function under test, technique and owner.
A6: Sheet 'Coverage Check': formulas that verify the rule '5 to 10 tests per person for each function and for each class / module'.
A7: Sheet 'Known Defects': tests that are marked xfail because they document a real defect.
A9: To add a data-driven test: add a row to 'Data Driven Cases' (and a CSV in tests/data), then add a handler with the same name in tests/data_driven/test_excel_driven.py. Re-generate this workbook with: python tools/generate_excel.py

Sheet Data Driven Cases
A1: Test Case ID | B1: Module | C1: Function Under Test | D1: Handler | E1: Technique | F1: Description | G1: Test Data File | H1: Data Columns | I1: Expected Result Rule | J1: Owner | K1: Priority | L1: Data Rows
A2: DD-01 | B2: Module 1 - Grading | C2: grade_from_percentage | D2: grade_from_percentage | E2: BVA + ECP | F2: Every row of the CSV is a percentage; the grade returned must equal expected_grade (values on and next to each cut-off). | G2: grade_boundaries.csv | H2: percentage, expected_grade | I2: grade_from_percentage(percentage) == expected_grade | J2: Maryam Fatima | K2: High | L2: 6
A3: DD-02 | B3: Module 1 - Grading | C3: grade_color | D3: grade_color | E3: ECP | F3: Every grade (and the '-' placeholder) must map to the expected colour constant (GREEN, BLUE, ORANGE or RED). | G3: grade_colors.csv | H3: grade, expected_color | I3: grade_color(grade) == student_portal.<expected_color> | J3: Huda Asif | K3: Medium | L3: 4
A4: DD-03 | B4: Module 3 - StudentDashboard | C4: StudentDashboard.overall_attendance | D4: overall_attendance | E4: ECP + BVA | F4: A pipe-separated list of statuses is turned into attendance records; total, present and percentage must match. | G4: attendance_cases.csv | H4: case_id, statuses, expected_total, expected_present, expected_percent | I4: overall_attendance(records) == (expected_total, expected_present, expected_percent) | J4: Huda Asif | K4: High | L4: 5
A5: DD-04 | B5: Module 3 - StudentDashboard | C5: StudentDashboard.average_grade | D5: average_grade | E5: ECP + BVA | F5: Result percentages and approval flags are turned into result records; grade, count and average must match. | G5: average_grade_cases.csv | H5: case_id, percentages, approved, expected_grade, expected_count, expected_average | I5: average_grade(records) == (expected_grade, expected_count, expected_average) | J5: Maryam Fatima | K5: High | L5: 5
A6: DD-05 | B6: Module 2 - Storage | C6: Storage.set / Storage.get | D6: storage_round_trip | E6: ECP | F6: A JSON value is saved with set(), the application is 'restarted' (new Storage) and get() must return the same value. | G6: storage_roundtrip.csv | H6: case_id, key, json_value | I6: Storage().get(key) == json.loads(json_value) after set() | J6: Maryam Fatima | K6: Medium | L6: 4

Sheet Test Inventory
A1: Test ID | B1: Module | C1: Function / Class Under Test | D1: Test Function | E1: What it checks | F1: Technique | G1: Owner | H1: Executed Cases | I1: Markers (groups) | J1: File
A2: UT-001 | B2: Module 1 - Grading | C2: grade_from_percentage() | D2: test_negative_percentage_is_graded_f | E2: Values below the valid range 0..100 currently return F (no validation). | F2: ECP-invalid | G2: Huda Asif | H2: 2 | I2: negative | J2: tests/unit/grading/test_grading_huda.py
A3: UT-002 | B3: Module 1 - Grading | C3: grade_from_percentage() | D3: test_percentage_above_100_is_graded_a_plus | E3: Values above 100 currently return A+ (there is no upper limit check). | F3: ECP-invalid | G3: Huda Asif | H3: 2 | I3: negative | J3: tests/unit/grading/test_grading_huda.py
A4: UT-003 | B4: Module 1 - Grading | C4: grade_from_percentage() | D4: test_floating_point_values_next_to_a_cutoff | E4: Tiny differences around the 90 cut-off decide the grade correctly. | F4: BVA | G4: Huda Asif | H4: 1 | I4: boundary | J4: tests/unit/grading/test_grading_huda.py
A5: UT-004 | B5: Module 1 - Grading | C5: grade_from_percentage() | D5: test_nan_is_graded_f_without_an_error | E5: NaN fails every comparison, so it silently becomes F. | F5: EG | G5: Huda Asif | H5: 1 | I5: negative | J5: tests/unit/grading/test_grading_huda.py
A6: UT-005 | B6: Module 1 - Grading | C6: grade_from_percentage() | D6: test_non_numeric_input_raises_type_error | E6: None, text, list and dict are not numbers and raise TypeError. | F6: ECP-invalid | G6: Huda Asif | H6: 2 | I6: negative | J6: tests/unit/grading/test_grading_huda.py
A7: UT-006 | B7: Module 1 - Grading | C7: grade_color() | D7: test_placeholder_or_empty_grade_is_red | E7: The '-' shown before marks are entered, and '', fall through to RED. | F7: ECP-invalid | G7: Huda Asif | H7: 2 | I7: negative | J7: tests/unit/grading/test_grading_huda.py
A8: UT-007 | B8: Module 1 - Grading | C8: grade_color() | D8: test_lowercase_grades_are_not_recognised | E8: The check is case-sensitive, so lowercase grades are RED. | F8: EG | G8: Huda Asif | H8: 2 | I8: negative | J8: tests/unit/grading/test_grading_huda.py
A9: UT-008 | B9: Module 1 - Grading | C9: grade_color() | D9: test_grade_with_leading_whitespace_is_red | E9: A grade that starts with a space or tab does not match 'A'/'B'/'C'. | F9: EG | G9: Huda Asif | H9: 2 | I9: negative | J9: tests/unit/grading/test_grading_huda.py
A10: UT-009 | B10: Module 1 - Grading | C10: grade_color() | D10: test_non_string_input_raises_attribute_error | E10: startswith() does not exist on non-strings, so AttributeError is raised. | F10: ECP-invalid | G10: Huda Asif | H10: 2 | I10: negative | J10: tests/unit/grading/test_grading_huda.py
A11: UT-010 | B11: Module 1 - Grading | C11: grade_color() | D11: test_any_text_starting_with_a_is_green | E11: Characterisation: the function checks only the first letter, so 'Apple' is GREEN. | F11: EG | G11: Huda Asif | H11: 1 | J11: tests/unit/grading/test_grading_huda.py
A12: UT-011 | B12: Module 1 - Grading | C12: MODULE: grading scale | D12: test_colour_constants_are_distinct_hex_codes | E12: GREEN, BLUE, ORANGE and RED are four different #rrggbb values. | F12: ECP | G12: Huda Asif | H12: 1 | J12: tests/unit/grading/test_grading_huda.py
A13: UT-012 | B13: Module 1 - Grading | C13: MODULE: grading scale | D13: test_functions_are_deterministic | E13: Calling 1000 times with the same input always gives the same output (no hidden state). | F13: EG | G13: Huda Asif | H13: 1 | J13: tests/unit/grading/test_grading_huda.py
A14: UT-013 | B14: Module 1 - Grading | C14: MODULE: grading scale | D14: test_accepts_any_numeric_type | E14: int, float, Decimal and Fraction behave the same for the same value. | F14: ECP | G14: Huda Asif | H14: 2 | J14: tests/unit/grading/test_grading_huda.py
A15: UT-014 | B15: Module 1 - Grading | C15: MODULE: grading scale | D15: test_extreme_magnitudes_and_infinity | E15: Huge numbers and +-infinity are clamped by the comparisons (A+ / F). | F15: BVA | G15: Huda Asif | H15: 1 | I15: boundary | J15: tests/unit/grading/test_grading_huda.py
A16: UT-015 | B16: Module 1 - Grading | C16: MODULE: grading scale | D16: test_marks_to_colour_pipeline_including_total_of_one | E16: marks -> percentage -> grade -> colour, including the smallest total (1). | F16: BVA | G16: Huda Asif | H16: 2 | J16: tests/unit/grading/test_grading_huda.py
A17: UT-016 | B17: Module 1 - Grading | C17: grade_from_percentage() | D17: test_value_exactly_on_a_cutoff_gets_the_higher_grade | E17: On-boundary values: a percentage equal to a cut-off belongs to the higher grade. | F17: BVA | G17: Maryam Fatima | H17: 4 | I17: smoke, boundary, execution_order=1 | J17: tests/unit/grading/test_grading_maryam.py
A18: UT-017 | B18: Module 1 - Grading | C18: grade_from_percentage() | D18: test_value_just_below_a_cutoff_gets_the_lower_grade | E18: Off-boundary values: 0.01 below each cut-off falls into the next lower grade. | F18: BVA | G18: Maryam Fatima | H18: 3 | I18: boundary | J18: tests/unit/grading/test_grading_maryam.py
A19: UT-018 | B19: Module 1 - Grading | C19: grade_from_percentage() | D19: test_typical_value_inside_each_grade_band | E19: One representative value from the middle of every valid grade band. | F19: ECP | G19: Maryam Fatima | H19: 3 | I19: equivalence | J19: tests/unit/grading/test_grading_maryam.py
A20: UT-019 | B20: Module 1 - Grading | C20: grade_from_percentage() | D20: test_extreme_valid_values_0_and_100 | E20: The two ends of the valid range 0..100. | F20: BVA | G20: Maryam Fatima | H20: 1 | I20: boundary | J20: tests/unit/grading/test_grading_maryam.py
A21: UT-020 | B21: Module 1 - Grading | C21: grade_from_percentage() | D21: test_every_whole_percentage_returns_a_known_grade | E21: Output domain: every whole percentage 0..100 maps to one of the 10 defined grades. | F21: ECP | G21: Maryam Fatima | H21: 1 | I21: equivalence | J21: tests/unit/grading/test_grading_maryam.py
A22: UT-021 | B22: Module 1 - Grading | C22: grade_color() | D22: test_a_grades_are_green | E22: Class 'A family' -> GREEN. | F22: ECP | G22: Maryam Fatima | H22: 1 | I22: smoke, equivalence | J22: tests/unit/grading/test_grading_maryam.py
A23: UT-022 | B23: Module 1 - Grading | C23: grade_color() | D23: test_b_grades_are_blue | E23: Class 'B family' -> BLUE. | F23: ECP | G23: Maryam Fatima | H23: 1 | I23: equivalence | J23: tests/unit/grading/test_grading_maryam.py
A24: UT-023 | B24: Module 1 - Grading | C24: grade_color() | D24: test_c_grades_are_orange | E24: Class 'C family' -> ORANGE. | F24: ECP | G24: Maryam Fatima | H24: 1 | I24: equivalence | J24: tests/unit/grading/test_grading_maryam.py
A25: UT-024 | B25: Module 1 - Grading | C25: grade_color() | D25: test_fail_grade_is_red | E25: Class 'fail' -> RED. | F25: ECP | G25: Maryam Fatima | H25: 1 | I25: equivalence | J25: tests/unit/grading/test_grading_maryam.py
A26: UT-025 | B26: Module 1 - Grading | C26: grade_color() | D26: test_every_grade_returns_a_hex_colour_code | E26: The result is always a valid #rrggbb colour string. | F26: ECP | G26: Maryam Fatima | H26: 3 | I26: equivalence | J26: tests/unit/grading/test_grading_maryam.py
A27: UT-026 | B27: Module 1 - Grading | C27: MODULE: grading scale | D27: test_scale_is_monotonic_a_higher_percentage_never_gives_a_lower_grade | E27: Walking from 0 to 100 in steps of 0.5 the grade rank never goes down. | F27: BVA | G27: Maryam Fatima | H27: 1 | I27: smoke, execution_order=2 | J27: tests/unit/grading/test_grading_maryam.py
A28: UT-027 | B28: Module 1 - Grading | C28: MODULE: grading scale | D28: test_scale_has_exactly_ten_distinct_grades | E28: Across 0..100 all 10 grades are reachable and no other value appears. | F28: ECP | G28: Maryam Fatima | H28: 1 | J28: tests/unit/grading/test_grading_maryam.py
A29: UT-028 | B29: Module 1 - Grading | C29: MODULE: grading scale | D29: test_pass_fail_line_is_at_50_percent | E29: 50 is the lowest passing mark (C-), 49 and below is F. | F29: BVA | G29: Maryam Fatima | H29: 1 | I29: boundary | J29: tests/unit/grading/test_grading_maryam.py
A30: UT-029 | B30: Module 1 - Grading | C30: MODULE: grading scale | D30: test_colour_bands_follow_percentage_ranges | E30: >=80 green, 65-79 blue, 50-64 orange, <50 red, for every whole percentage. | F30: ECP | G30: Maryam Fatima | H30: 1 | J30: tests/unit/grading/test_grading_maryam.py
A31: UT-030 | B31: Module 1 - Grading | C31: MODULE: grading scale | D31: test_marks_to_grade_pipeline_for_typical_exams | E31: The app computes marks / total * 100 and then the grade; check realistic exams. | F31: ECP | G31: Maryam Fatima | H31: 1 | J31: tests/unit/grading/test_grading_maryam.py
A32: UT-031 | B32: Module 2 - Storage | C32: Storage.get() | D32: test_empty_string_key_returns_an_empty_list | E32: Shortest possible key (empty string) works and creates an empty list. | F32: BVA | G32: Huda Asif | H32: 1 | I32: negative | J32: tests/unit/storage/test_storage_huda.py
A33: UT-032 | B33: Module 2 - Storage | C33: Storage.get() | D33: test_unicode_key_is_supported | E33: Keys in Urdu script are valid dictionary keys. | F33: EG | G33: Huda Asif | H33: 1 | I33: equivalence | J33: tests/unit/storage/test_storage_huda.py
A34: UT-033 | B34: Module 2 - Storage | C34: Storage.get() | D34: test_get_does_not_write_the_file | E34: The key created by get() exists only in memory until save() is called. | F34: EG | G34: Huda Asif | H34: 1 | I34: state | J34: tests/unit/storage/test_storage_huda.py
A35: UT-034 | B35: Module 2 - Storage | C35: Storage.get() | D35: test_get_returns_what_set_stored | E35: set() followed by get() returns the identical object. | F35: EG | G35: Huda Asif | H35: 1 | I35: state | J35: tests/unit/storage/test_storage_huda.py
A36: UT-035 | B36: Module 2 - Storage | C36: Storage.get() | D36: test_changes_made_through_get_are_saved_only_after_save | E36: Editing the list from get() is lost on restart unless save() is called. | F36: EG | G36: Huda Asif | H36: 1 | I36: state | J36: tests/unit/storage/test_storage_huda.py
A37: UT-036 | B37: Module 2 - Storage | C37: Storage.set() | D37: test_none_value_is_stored_and_returned_by_get | E37: None is a valid JSON null; get() returns None because the key exists. | F37: EG | G37: Huda Asif | H37: 1 | I37: negative | J37: tests/unit/storage/test_storage_huda.py
A38: UT-037 | B38: Module 2 - Storage | C38: Storage.set() | D38: test_value_that_is_not_json_serialisable_raises_type_error | E38: A Python set cannot be written as JSON, so TypeError is raised. | F38: ECP-invalid | G38: Huda Asif | H38: 1 | I38: negative | J38: tests/unit/storage/test_storage_huda.py
A39: UT-038 | B39: Module 2 - Storage | C39: Storage.set() | D39: test_failed_save_leaves_memory_and_disk_different | E39: set() changes memory first: after the TypeError the bad value is still in memory. | F39: EG | G39: Huda Asif | H39: 1 | I39: negative, state | J39: tests/unit/storage/test_storage_huda.py
A40: UT-039 | B40: Module 2 - Storage | C40: Storage.set() | D40: test_urdu_text_round_trips_through_the_file | E40: Non-ASCII text survives set() -> restart -> get(). | F40: EG | G40: Huda Asif | H40: 1 | I40: equivalence | J40: tests/unit/storage/test_storage_huda.py
...

Sheet Coverage Check
A3: Module | B3: Function / Class Under Test | C3: Maryam Fatima | D3: Huda Asif | E3: Both | F3: Status
A4: Module 1 - Grading | B4: grade_from_percentage() | C4: =COUNTIFS('Test Inventory'!$B$2:$B$112,$A4,'Test Inventory'!$C$2:$C$112,$B4,'Test Inventory'!$G$2:$G$112,C$3) -> 5 | D4: =COUNTIFS('Test Inventory'!$B$2:$B$112,$A4,'Test Inventory'!$C$2:$C$112,$B4,'Test Inventory'!$G$2:$G$112,D$3) -> 5 | E4: =C4+D4 -> 10 | F4: =IF(AND(C4>=5,C4<=10,D4>=5,D4<=10),"OK","CHECK") -> OK
A5: Module 1 - Grading | B5: grade_color() | C5: =COUNTIFS('Test Inventory'!$B$2:$B$112,$A5,'Test Inventory'!$C$2:$C$112,$B5,'Test Inventory'!$G$2:$G$112,C$3) -> 5 | D5: =COUNTIFS('Test Inventory'!$B$2:$B$112,$A5,'Test Inventory'!$C$2:$C$112,$B5,'Test Inventory'!$G$2:$G$112,D$3) -> 5 | E5: =C5+D5 -> 10 | F5: =IF(AND(C5>=5,C5<=10,D5>=5,D5<=10),"OK","CHECK") -> OK
A6: Module 1 - Grading | B6: MODULE: grading scale | C6: =COUNTIFS('Test Inventory'!$B$2:$B$112,$A6,'Test Inventory'!$C$2:$C$112,$B6,'Test Inventory'!$G$2:$G$112,C$3) -> 5 | D6: =COUNTIFS('Test Inventory'!$B$2:$B$112,$A6,'Test Inventory'!$C$2:$C$112,$B6,'Test Inventory'!$G$2:$G$112,D$3) -> 5 | E6: =C6+D6 -> 10 | F6: =IF(AND(C6>=5,C6<=10,D6>=5,D6<=10),"OK","CHECK") -> OK
A7: Module 2 - Storage | B7: Storage.get() | C7: =COUNTIFS('Test Inventory'!$B$2:$B$112,$A7,'Test Inventory'!$C$2:$C$112,$B7,'Test Inventory'!$G$2:$G$112,C$3) -> 5 | D7: =COUNTIFS('Test Inventory'!$B$2:$B$112,$A7,'Test Inventory'!$C$2:$C$112,$B7,'Test Inventory'!$G$2:$G$112,D$3) -> 5 | E7: =C7+D7 -> 10 | F7: =IF(AND(C7>=5,C7<=10,D7>=5,D7<=10),"OK","CHECK") -> OK
A8: Module 2 - Storage | B8: Storage.set() | C8: =COUNTIFS('Test Inventory'!$B$2:$B$112,$A8,'Test Inventory'!$C$2:$C$112,$B8,'Test Inventory'!$G$2:$G$112,C$3) -> 5 | D8: =COUNTIFS('Test Inventory'!$B$2:$B$112,$A8,'Test Inventory'!$C$2:$C$112,$B8,'Test Inventory'!$G$2:$G$112,D$3) -> 5 | E8: =C8+D8 -> 10 | F8: =IF(AND(C8>=5,C8<=10,D8>=5,D8<=10),"OK","CHECK") -> OK
A9: Module 2 - Storage | B9: Storage.log_activity() | C9: =COUNTIFS('Test Inventory'!$B$2:$B$112,$A9,'Test Inventory'!$C$2:$C$112,$B9,'Test Inventory'!$G$2:$G$112,C$3) -> 5 | D9: =COUNTIFS('Test Inventory'!$B$2:$B$112,$A9,'Test Inventory'!$C$2:$C$112,$B9,'Test Inventory'!$G$2:$G$112,D$3) -> 5 | E9: =C9+D9 -> 10 | F9: =IF(AND(C9>=5,C9<=10,D9>=5,D9<=10),"OK","CHECK") -> OK
A10: Module 2 - Storage | B10: CLASS: Storage | C10: =COUNTIFS('Test Inventory'!$B$2:$B$112,$A10,'Test Inventory'!$C$2:$C$112,$B10,'Test Inventory'!$G$2:$G$112,C$3) -> 5 | D10: =COUNTIFS('Test Inventory'!$B$2:$B$112,$A10,'Test Inventory'!$C$2:$C$112,$B10,'Test Inventory'!$G$2:$G$112,D$3) -> 5 | E10: =C10+D10 -> 10 | F10: =IF(AND(C10>=5,C10<=10,D10>=5,D10<=10),"OK","CHECK") -> OK
A11: Module 3 - StudentDashboard | B11: StudentDashboard.overall_attendance() | C11: =COUNTIFS('Test Inventory'!$B$2:$B$112,$A11,'Test Inventory'!$C$2:$C$112,$B11,'Test Inventory'!$G$2:$G$112,C$3) -> 5 | D11: =COUNTIFS('Test Inventory'!$B$2:$B$112,$A11,'Test Inventory'!$C$2:$C$112,$B11,'Test Inventory'!$G$2:$G$112,D$3) -> 5 | E11: =C11+D11 -> 10 | F11: =IF(AND(C11>=5,C11<=10,D11>=5,D11<=10),"OK","CHECK") -> OK
A12: Module 3 - StudentDashboard | B12: StudentDashboard.average_grade() | C12: =COUNTIFS('Test Inventory'!$B$2:$B$112,$A12,'Test Inventory'!$C$2:$C$112,$B12,'Test Inventory'!$G$2:$G$112,C$3) -> 5 | D12: =COUNTIFS('Test Inventory'!$B$2:$B$112,$A12,'Test Inventory'!$C$2:$C$112,$B12,'Test Inventory'!$G$2:$G$112,D$3) -> 5 | E12: =C12+D12 -> 10 | F12: =IF(AND(C12>=5,C12<=10,D12>=5,D12<=10),"OK","CHECK") -> OK
A13: Module 3 - StudentDashboard | B13: StudentDashboard.load_course_wise_attendance() | C13: =COUNTIFS('Test Inventory'!$B$2:$B$112,$A13,'Test Inventory'!$C$2:$C$112,$B13,'Test Inventory'!$G$2:$G$112,C$3) -> 5 | D13: =COUNTIFS('Test Inventory'!$B$2:$B$112,$A13,'Test Inventory'!$C$2:$C$112,$B13,'Test Inventory'!$G$2:$G$112,D$3) -> 5 | E13: =C13+D13 -> 10 | F13: =IF(AND(C13>=5,C13<=10,D13>=5,D13<=10),"OK","CHECK") -> OK
A14: Module 3 - StudentDashboard | B14: CLASS: StudentDashboard | C14: =COUNTIFS('Test Inventory'!$B$2:$B$112,$A14,'Test Inventory'!$C$2:$C$112,$B14,'Test Inventory'!$G$2:$G$112,C$3) -> 6 | D14: =COUNTIFS('Test Inventory'!$B$2:$B$112,$A14,'Test Inventory'!$C$2:$C$112,$B14,'Test Inventory'!$G$2:$G$112,D$3) -> 5 | E14: =C14+D14 -> 11 | F14: =IF(AND(C14>=5,C14<=10,D14>=5,D14<=10),"OK","CHECK") -> OK
B15: Total test functions | C15: =SUM(C4:C14) -> 56 | D15: =SUM(D4:D14) -> 55 | E15: =SUM(E4:E14) -> 111
A17: Executed cases (including parametrised variants) | C17: =SUMIFS('Test Inventory'!$H$2:$H$112,'Test Inventory'!$G$2:$G$112,C$3) -> 69 | D17: =SUMIFS('Test Inventory'!$H$2:$H$112,'Test Inventory'!$G$2:$G$112,D$3) -> 65 | E17: =C17+D17 -> 134

Sheet Known Defects
A1: Defect ID | B1: Description | C1: Test Function | D1: Origin
A2: UT-DEF-01 | B2: Storage() crashes with AttributeError when portal_data.json holds valid JSON that is not an object (for example [] or null) | C2: test_json_file_that_is_not_an_object_does_not_crash_the_app | D2: New defect found by unit tests
A3: UT-DEF-02 | B3: save() opens the file with 'w' before json.dump(), so a serialisation error leaves a truncated, unreadable data file on disk (all data lost) | C3: test_failed_save_keeps_the_previous_file_valid | D3: New defect found by unit tests
A4: UT-DEF-03 | B4: overall_attendance() rounds to a whole number, so 74.7 % becomes 75 % and the dashboard (which checks pct < 75) shows no low-attendance warning | C4: test_attendance_below_75_percent_is_not_rounded_up_to_75 | D4: New defect found by unit tests
A5: DEF-014 (Assignment 2) / UT-DEF-04 | B5: grade_from_percentage has no input validation; a negative percentage is graded 'F' and a percentage above 100 is graded 'A+' instead of being rejected | C5: test_out_of_range_percentage_is_rejected | D5: Assignment 2 defect confirmed at unit level
A6: DEF-015 (Assignment 2) | B6: invalid values are silently accepted; NaN is graded 'F' instead of being rejected | C6: test_nan_percentage_is_rejected | D6: Assignment 2 defect confirmed at unit level
A7: DEF-023 (Assignment 2) | B7: a corrupted data file is silently replaced by seed data; no backup copy of the damaged file is kept | C7: test_corrupt_data_file_is_backed_up_before_it_is_replaced | D7: Assignment 2 defect confirmed at unit level
